Workbook
Name average: Info!$Q$9
Name Birth: Calc!$B$14
Name birthday: Calc!$B$17
Name Gauge: Calc!$E$34
Name Slicer_ماه: #N/A
Name title: Calc!$K$33
Name Total: Calc!$A$12

Sheet Sheet11
A1: Data returned for Count of جنسیت, زن, All (First 1000 rows).
A3: Info[کد پرسنلی] | B3: Info[دپارتمان] | C3: Info[نام] | D3: Info[جنسیت] | E3: Info[نوع قرارداد] | F3: Info[تاریخ تولد] | G3: Info[سن] | H3: Info[ماه تولد]
A4: 9987656 | B4: فناوری اطلاعات | C4: سیما رضوی | D4: زن | E4: تمام وقت | F4: 33893 | G4: 29 | H4: 7
A5: 9987728 | B5: کنترل هزینه | C5: هدا محمدی | D5: زن | E5: پاره وقت | F5: 33626 | G5: 30 | H5: 11
A6: 9987938 | B6: مهندسی | C6: نیلوفر محبی | D6: زن | E6: تمام وقت | F6: 32825 | G6: 32 | H6: 8
A7: 9988137 | B7: منابع انسانی | C7: شیرین مولودی | D7: زن | E7: پاره وقت | F7: 32024 | G7: 34 | H7: 6
A8: 9988371 | B8: منابع انسانی | C8: شیدا ضیایی | D8: زن | E8: تمام وقت | F8: 30956 | G8: 37 | H8: 7
A9: 9988453 | B9: منابع انسانی | C9: بهار رستمی | D9: زن | E9: تمام وقت | F9: 30422 | G9: 38 | H9: 1
A10: 9988492 | B10: حقوقی و قراردادی | C10: ندا گرگانی | D10: زن | E10: تمام وقت | F10: 30155 | G10: 39 | H10: 5
A11: 9988657 | B11: کنترل هزینه | C11: نعیمه بهبهانی | D11: زن | E11: پاره وقت | F11: 29354 | G11: 41 | H11: 2
A12: 9988725 | B12: کنترل هزینه | C12: زهرا مینایی | D12: زن | E12: پاره وقت | F12: 28820 | G12: 43 | H12: 9
A13: 9988917 | B13: حقوقی و قراردادی | C13: فاطمه طالکویی | D13: زن | E13: تمام وقت | F13: 33092 | G13: 31 | H13: 5
A14: 9988965 | B14: مهندسی | C14: اشرف زومند | D14: زن | E14: تمام وقت | F14: 32825 | G14: 32 | H14: 8
A15: 9989397 | B15: مهندسی | C15: هما سلیمی | D15: زن | E15: تمام وقت | F15: 30422 | G15: 38 | H15: 1
... A22: 9990597 | B22: مهندسی | C22: انیس طاهری | D22: زن | E22: تمام وقت | F22: 29087 | G22: 42 | H22: 5

Sheet Calc
A1: ماه | B1: فروردین
A3: Row Labels | B3: Count of جنسیت | E3: Count of جنسیت | F3: Column Labels
A4: زن | B4: 19 | E4: Row Labels | F4: زن | G4: مرد | H4: Grand Total
A5: مرد | B5: 41 | E5: حقوقی و قراردادی | F5: 2 | G5: 6 | H5: 8
A6: Grand Total | B6: 60 | E6: فناوری اطلاعات | F6: 2 | G6: 6 | H6: 8
E7: کنترل هزینه | F7: 5 | G7: 11 | H7: 16
E8: منابع انسانی | F8: 4 | G8: 9 | H8: 13
E9: مهندسی | F9: 6 | G9: 9 | H9: 15
A10: =AVERAGE(B4:B5) -> 30 | E10: Grand Total | F10: 19 | G10: 41 | H10: 60 | O10: 1
O11: 3
A12: =B6 -> 60 | O12: 2
A16: فروردین | B16: =MATCH(B1,A16:A27,0) -> 1
A17: اردیبهشت | B17: =COUNTIF(Info[ماه تولد],Calc!B16) -> 3
A18: خرداد | E18: Count of جنسیت | F18: Column Labels | K18: تمام وقت | L18: =H21 -> 42
A19: تیر | E19: Row Labels | F19: زن | G19: مرد | H19: Grand Total | K19: مرد | L19: =G20 -> 13
A20: مرداد | E20: پاره وقت | F20: 5 | G20: 13 | H20: 18 | K20: زن | L20: =F20 -> 5
A21: شهریور | E21: تمام وقت | F21: 14 | G21: 28 | H21: 42
A22: مهر | E22: Grand Total | F22: 19 | G22: 41 | H22: 60
A23: آبان
A24: آذر
A25: دی
A26: بهمن | I26: ROUND(AVERAGEIFS(Salary[شاخص ارزیابی],Salary[ماه],Calc!B1),0)
A27: اسفند
E29: =ROUND(AVERAGEIFS(Salary[شاخص ارزیابی],Salary[ماه],Calc!B1),0) -> 66
E30: 2
E31: =100-E29-E30 -> 32
E32: 100
K33: =" تعداد افراد ماه " & B1 -> تعداد افراد ماه فروردین
E34: ="میانگین شاخص ارزیابی کارکنان در ماه " &B1 -> میانگین شاخص ارزیابی کارکنان در ماه فروردین

Sheet Info
A1: کد پرسنلی | B1: دپارتمان | C1: نام | D1: جنسیت | E1: نوع قرارداد | F1: تاریخ تولد | G1: سن | H1: ماه تولد
A2: 9987656 | B2: فناوری اطلاعات | C2: سیما رضوی | D2: زن | E2: تمام وقت | F2: 33893 | G2: =QUOTIENT(TODAY()-Info[[#This Row],[تاریخ تولد]],365) -> 33 | H2: =--TEXT(Info[[#This Row],[تاریخ تولد]],"[$-fa-IR,96]mm") -> 7
A3: 9987728 | B3: کنترل هزینه | C3: هدا محمدی | D3: زن | E3: پاره وقت | F3: 33626 | G3: =QUOTIENT(TODAY()-Info[[#This Row],[تاریخ تولد]],365) -> 33 | H3: =--TEXT(Info[[#This Row],[تاریخ تولد]],"[$-fa-IR,96]mm") -> 11
A4: 9987826 | B4: منابع انسانی | C4: رضا ابدی | D4: مرد | E4: تمام وقت | F4: 33359 | G4: =QUOTIENT(TODAY()-Info[[#This Row],[تاریخ تولد]],365) -> 34 | H4: =--TEXT(Info[[#This Row],[تاریخ تولد]],"[$-fa-IR,96]mm") -> 2
A5: 9987915 | B5: حقوقی و قراردادی | C5: محمود قیصری | D5: مرد | E5: تمام وقت | F5: 33092 | G5: =QUOTIENT(TODAY()-Info[[#This Row],[تاریخ تولد]],365) -> 35 | H5: =--TEXT(Info[[#This Row],[تاریخ تولد]],"[$-fa-IR,96]mm") -> 5
A6: 9987938 | B6: مهندسی | C6: نیلوفر محبی | D6: زن | E6: تمام وقت | F6: 32825 | G6: =QUOTIENT(TODAY()-Info[[#This Row],[تاریخ تولد]],365) -> 36 | H6: =--TEXT(Info[[#This Row],[تاریخ تولد]],"[$-fa-IR,96]mm") -> 8
A7: 9988023 | B7: فناوری اطلاعات | C7: ایمان کیایی | D7: مرد | E7: تمام وقت | F7: 32558 | G7: =QUOTIENT(TODAY()-Info[[#This Row],[تاریخ تولد]],365) -> 36 | H7: =--TEXT(Info[[#This Row],[تاریخ تولد]],"[$-fa-IR,96]mm") -> 11
A8: 9988106 | B8: کنترل هزینه | C8: نیما موحدی | D8: مرد | E8: تمام وقت | F8: 32291 | G8: =QUOTIENT(TODAY()-Info[[#This Row],[تاریخ تولد]],365) -> 37 | H8: =--TEXT(Info[[#This Row],[تاریخ تولد]],"[$-fa-IR,96]mm") -> 3
A9: 9988137 | B9: منابع انسانی | C9: شیرین مولودی | D9: زن | E9: پاره وقت | F9: 32024 | G9: =QUOTIENT(TODAY()-Info[[#This Row],[تاریخ تولد]],365) -> 38 | H9: =--TEXT(Info[[#This Row],[تاریخ تولد]],"[$-fa-IR,96]mm") -> 6 | Q9: =AVERAGE(Info[سن]) -> 39.6
A10: 9988165 | B10: حقوقی و قراردادی | C10: محمد کریمی | D10: مرد | E10: پاره وقت | F10: 31757 | G10: =QUOTIENT(TODAY()-Info[[#This Row],[تاریخ تولد]],365) -> 38 | H10: =--TEXT(Info[[#This Row],[تاریخ تولد]],"[$-fa-IR,96]mm") -> 9
A11: 9988236 | B11: مهندسی | C11: نیکان علوی | D11: مرد | E11: تمام وقت | F11: 31490 | G11: =QUOTIENT(TODAY()-Info[[#This Row],[تاریخ تولد]],365) -> 39 | H11: =--TEXT(Info[[#This Row],[تاریخ تولد]],"[$-fa-IR,96]mm") -> 12
A12: 9988277 | B12: کنترل هزینه | C12: سینا راد | D12: مرد | E12: تمام وقت | F12: 31223 | G12: =QUOTIENT(TODAY()-Info[[#This Row],[تاریخ تولد]],365) -> 40 | H12: =--TEXT(Info[[#This Row],[تاریخ تولد]],"[$-fa-IR,96]mm") -> 4
A13: 9988371 | B13: منابع انسانی | C13: شیدا ضیایی | D13: زن | E13: تمام وقت | F13: 30956 | G13: =QUOTIENT(TODAY()-Info[[#This Row],[تاریخ تولد]],365) -> 41 | H13: =--TEXT(Info[[#This Row],[تاریخ تولد]],"[$-fa-IR,96]mm") -> 7
A14: 9988393 | B14: کنترل هزینه | C14: حسن تاج | D14: مرد | E14: تمام وقت | F14: 30689 | G14: =QUOTIENT(TODAY()-Info[[#This Row],[تاریخ تولد]],365) -> 41 | H14: =--TEXT(Info[[#This Row],[تاریخ تولد]],"[$-fa-IR,96]mm") -> 10
A15: 9988453 | B15: منابع انسانی | C15: بهار رستمی | D15: زن | E15: تمام وقت | F15: 30422 | G15: =QUOTIENT(TODAY()-Info[[#This Row],[تاریخ تولد]],365) -> 42 | H15: =--TEXT(Info[[#This Row],[تاریخ تولد]],"[$-fa-IR,96]mm") -> 1
A16: 9988492 | B16: حقوقی و قراردادی | C16: ندا گرگانی | D16: زن | E16: تمام وقت | F16: 30155 | G16: =QUOTIENT(TODAY()-Info[[#This Row],[تاریخ تولد]],365) -> 43 | H16: =--TEXT(Info[[#This Row],[تاریخ تولد]],"[$-fa-IR,96]mm") -> 5
A17: 9988572 | B17: مهندسی | C17: علی اسفندیاری | D17: مرد | E17: تمام وقت | F17: 29888 | G17: =QUOTIENT(TODAY()-Info[[#This Row],[تاریخ تولد]],365) -> 44 | H17: =--TEXT(Info[[#This Row],[تاریخ تولد]],"[$-fa-IR,96]mm") -> 8
A18: 9988618 | B18: فناوری اطلاعات | C18: امید ریگی | D18: مرد | E18: پاره وقت | F18: 29621 | G18: =QUOTIENT(TODAY()-Info[[#This Row],[تاریخ تولد]],365) -> 44 | H18: =--TEXT(Info[[#This Row],[تاریخ تولد]],"[$-fa-IR,96]mm") -> 11
A19: 9988657 | B19: کنترل هزینه | C19: نعیمه بهبهانی | D19: زن | E19: پاره وقت | F19: 29354 | G19: =QUOTIENT(TODAY()-Info[[#This Row],[تاریخ تولد]],365) -> 45 | H19: =--TEXT(Info[[#This Row],[تاریخ تولد]],"[$-fa-IR,96]mm") -> 2
A20: 9988677 | B20: منابع انسانی | C20: مصطفی صفایی | D20: مرد | E20: تمام وقت | F20: 29087 | G20: =QUOTIENT(TODAY()-Info[[#This Row],[تاریخ تولد]],365) -> 46 | H20: =--TEXT(Info[[#This Row],[تاریخ تولد]],"[$-fa-IR,96]mm") -> 5
A21: 9988725 | B21: کنترل هزینه | C21: زهرا مینایی | D21: زن | E21: پاره وقت | F21: 28820 | G21: =QUOTIENT(TODAY()-Info[[#This Row],[تاریخ تولد]],365) -> 47 | H21: =--TEXT(Info[[#This Row],[تاریخ تولد]],"[$-fa-IR,96]mm") -> 9
... A61: 9990645 | B61: کنترل هزینه | C61: شهرام مقدم | D61: مرد | E61: پاره وقت | F61: 28820 | G61: =QUOTIENT(TODAY()-Info[[#This Row],[تاریخ تولد]],365) -> 47 | H61: =--TEXT(Info[[#This Row],[تاریخ تولد]],"[$-fa-IR,96]mm") -> 9

Sheet Salary
A1: کد پرسنلی | B1: شاخص ارزیابی | C1: index | D1: ماه | E1: پایه حقوق | F1: پاداش | G1: ناخالص | H1: بیمه کارفرما | I1: بیمه | J1: مالیات | K1: خالص دریافتی
A2: 9987656 | B2: =RANDBETWEEN(30,100) -> 47 | C2: =MATCH(Salary[[#This Row],[ماه]],Calc!$A$16:$A$27,0) -> 1 | D2: فروردین | E2: =RANDBETWEEN(3000,15000)*1000 -> 8028000 | F2: =0.7*E2 -> 5619600 | G2: =E2+F2 -> 13647600 | H2: =0.23*E2 -> 1846440 | I2: =0.07*E2 -> 561960 | J2: =IF(Salary[[#This Row],[پایه حقوق]]<=5600000,0,(Salary[[#This Row],[پایه حقوق]]-5600000)*0.1) -> 242800 | K2: =G2-I2-J2 -> 12842840
A3: 9987728 | B3: =RANDBETWEEN(30,100) -> 90 | C3: =MATCH(Salary[[#This Row],[ماه]],Calc!$A$16:$A$27,0) -> 1 | D3: فروردین | E3: =RANDBETWEEN(3000,15000)*1000 -> 5756000 | G3: =E3+F3 -> 5756000 | H3: =0.23*E3 -> 1323880 | I3: =0.07*E3 -> 402920 | J3: =IF(Salary[[#This Row],[پایه حقوق]]<=5600000,0,(Salary[[#This Row],[پایه حقوق]]-5600000)*0.1) -> 15600 | K3: =G3-I3-J3 -> 5337480
A4: 9987826 | B4: =RANDBETWEEN(30,100) -> 71 | C4: =MATCH(Salary[[#This Row],[ماه]],Calc!$A$16:$A$27,0) -> 1 | D4: فروردین | E4: =RANDBETWEEN(3000,15000)*1000 -> 14962000 | G4: =E4+F4 -> 14962000 | H4: =0.23*E4 -> 3441260 | I4: =0.07*E4 -> 1047340 | J4: =IF(Salary[[#This Row],[پایه حقوق]]<=5600000,0,(Salary[[#This Row],[پایه حقوق]]-5600000)*0.1) -> 936200 | K4: =G4-I4-J4 -> 12978460
A5: 9987915 | B5: =RANDBETWEEN(30,100) -> 83 | C5: =MATCH(Salary[[#This Row],[ماه]],Calc!$A$16:$A$27,0) -> 1 | D5: فروردین | E5: =RANDBETWEEN(3000,15000)*1000 -> 12404000 | F5: =0.7*E5 -> 8682800 | G5: =E5+F5 -> 21086800 | H5: =0.23*E5 -> 2852920 | I5: =0.07*E5 -> 868280 | J5: =IF(Salary[[#This Row],[پایه حقوق]]<=5600000,0,(Salary[[#This Row],[پایه حقوق]]-5600000)*0.1) -> 680400 | K5: =G5-I5-J5 -> 19538120
A6: 9987938 | B6: =RANDBETWEEN(30,100) -> 30 | C6: =MATCH(Salary[[#This Row],[ماه]],Calc!$A$16:$A$27,0) -> 1 | D6: فروردین | E6: =RANDBETWEEN(3000,15000)*1000 -> 3656000 | G6: =E6+F6 -> 3656000 | H6: =0.23*E6 -> 840880 | I6: =0.07*E6 -> 255920 | J6: =IF(Salary[[#This Row],[پایه حقوق]]<=5600000,0,(Salary[[#This Row],[پایه حقوق]]-5600000)*0.1) -> 0 | K6: =G6-I6-J6 -> 3400080
A7: 9988023 | B7: =RANDBETWEEN(30,100) -> 59 | C7: =MATCH(Salary[[#This Row],[ماه]],Calc!$A$16:$A$27,0) -> 1 | D7: فروردین | E7: =RANDBETWEEN(3000,15000)*1000 -> 5975000 | G7: =E7+F7 -> 5975000 | H7: =0.23*E7 -> 1374250 | I7: =0.07*E7 -> 418250 | J7: =IF(Salary[[#This Row],[پایه حقوق]]<=5600000,0,(Salary[[#This Row],[پایه حقوق]]-5600000)*0.1) -> 37500 | K7: =G7-I7-J7 -> 5519250
A8: 9988106 | B8: =RANDBETWEEN(30,100) -> 92 | C8: =MATCH(Salary[[#This Row],[ماه]],Calc!$A$16:$A$27,0) -> 1 | D8: فروردین | E8: =RANDBETWEEN(3000,15000)*1000 -> 3391000 | G8: =E8+F8 -> 3391000 | H8: =0.23*E8 -> 779930 | I8: =0.07*E8 -> 237370 | J8: =IF(Salary[[#This Row],[پایه حقوق]]<=5600000,0,(Salary[[#This Row],[پایه حقوق]]-5600000)*0.1) -> 0 | K8: =G8-I8-J8 -> 3153630
A9: 9988137 | B9: =RANDBETWEEN(30,100) -> 90 | C9: =MATCH(Salary[[#This Row],[ماه]],Calc!$A$16:$A$27,0) -> 1 | D9: فروردین | E9: =RANDBETWEEN(3000,15000)*1000 -> 3047000 | F9: =0.7*E9 -> 2132900 | G9: =E9+F9 -> 5179900 | H9: =0.23*E9 -> 700810 | I9: =0.07*E9 -> 213290 | J9: =IF(Salary[[#This Row],[پایه حقوق]]<=5600000,0,(Salary[[#This Row],[پایه حقوق]]-5600000)*0.1) -> 0 | K9: =G9-I9-J9 -> 4966610
A10: 9988165 | B10: =RANDBETWEEN(30,100) -> 41 | C10: =MATCH(Salary[[#This Row],[ماه]],Calc!$A$16:$A$27,0) -> 1 | D10: فروردین | E10: =RANDBETWEEN(3000,15000)*1000 -> 5477000 | G10: =E10+F10 -> 5477000 | H10: =0.23*E10 -> 1259710 | I10: =0.07*E10 -> 383390 | J10: =IF(Salary[[#This Row],[پایه حقوق]]<=5600000,0,(Salary[[#This Row],[پایه حقوق]]-5600000)*0.1) -> 0 | K10: =G10-I10-J10 -> 5093610
A11: 9988236 | B11: =RANDBETWEEN(30,100) -> 76 | C11: =MATCH(Salary[[#This Row],[ماه]],Calc!$A$16:$A$27,0) -> 1 | D11: فروردین | E11: =RANDBETWEEN(3000,15000)*1000 -> 13522000 | F11: =0.7*E11 -> 9465400 | G11: =E11+F11 -> 22987400 | H11: =0.23*E11 -> 3110060 | I11: =0.07*E11 -> 946540 | J11: =IF(Salary[[#This Row],[پایه حقوق]]<=5600000,0,(Salary[[#This Row],[پایه حقوق]]-5600000)*0.1) -> 792200 | K11: =G11-I11-J11 -> 21248660
A12: 9988277 | B12: =RANDBETWEEN(30,100) -> 68 | C12: =MATCH(Salary[[#This Row],[ماه]],Calc!$A$16:$A$27,0) -> 1 | D12: فروردین | E12: =RANDBETWEEN(3000,15000)*1000 -> 7295000 | F12: =0.7*E12 -> 5106500 | G12: =E12+F12 -> 12401500 | H12: =0.23*E12 -> 1677850 | I12: =0.07*E12 -> 510650 | J12: =IF(Salary[[#This Row],[پایه حقوق]]<=5600000,0,(Salary[[#This Row],[پایه حقوق]]-5600000)*0.1) -> 169500 | K12: =G12-I12-J12 -> 11721350
A13: 9988371 | B13: =RANDBETWEEN(30,100) -> 42 | C13: =MATCH(Salary[[#This Row],[ماه]],Calc!$A$16:$A$27,0) -> 1 | D13: فروردین | E13: =RANDBETWEEN(3000,15000)*1000 -> 13805000 | G13: =E13+F13 -> 13805000 | H13: =0.23*E13 -> 3175150 | I13: =0.07*E13 -> 966350 | J13: =IF(Salary[[#This Row],[پایه حقوق]]<=5600000,0,(Salary[[#This Row],[پایه حقوق]]-5600000)*0.1) -> 820500 | K13: =G13-I13-J13 -> 12018150
A14: 9988393 | B14: =RANDBETWEEN(30,100) -> 45 | C14: =MATCH(Salary[[#This Row],[ماه]],Calc!$A$16:$A$27,0) -> 1 | D14: فروردین | E14: =RANDBETWEEN(3000,15000)*1000 -> 11238000 | G14: =E14+F14 -> 11238000 | H14: =0.23*E14 -> 2584740 | I14: =0.07*E14 -> 786660 | J14: =IF(Salary[[#This Row],[پایه حقوق]]<=5600000,0,(Salary[[#This Row],[پایه حقوق]]-5600000)*0.1) -> 563800 | K14: =G14-I14-J14 -> 9887540
A15: 9988453 | B15: =RANDBETWEEN(30,100) -> 70 | C15: =MATCH(Salary[[#This Row],[ماه]],Calc!$A$16:$A$27,0) -> 1 | D15: فروردین | E15: =RANDBETWEEN(3000,15000)*1000 -> 8785000 | G15: =E15+F15 -> 8785000 | H15: =0.23*E15 -> 2020550 | I15: =0.07*E15 -> 614950 | J15: =IF(Salary[[#This Row],[پایه حقوق]]<=5600000,0,(Salary[[#This Row],[پایه حقوق]]-5600000)*0.1) -> 318500 | K15: =G15-I15-J15 -> 7851550
A16: 9988492 | B16: =RANDBETWEEN(30,100) -> 77 | C16: =MATCH(Salary[[#This Row],[ماه]],Calc!$A$16:$A$27,0) -> 1 | D16: فروردین | E16: =RANDBETWEEN(3000,15000)*1000 -> 6220000 | G16: =E16+F16 -> 6220000 | H16: =0.23*E16 -> 1430600 | I16: =0.07*E16 -> 435400 | J16: =IF(Salary[[#This Row],[پایه حقوق]]<=5600000,0,(Salary[[#This Row],[پایه حقوق]]-5600000)*0.1) -> 62000 | K16: =G16-I16-J16 -> 5722600
A17: 9988572 | B17: =RANDBETWEEN(30,100) -> 75 | C17: =MATCH(Salary[[#This Row],[ماه]],Calc!$A$16:$A$27,0) -> 1 | D17: فروردین | E17: =RANDBETWEEN(3000,15000)*1000 -> 10269000 | G17: =E17+F17 -> 10269000 | H17: =0.23*E17 -> 2361870 | I17: =0.07*E17 -> 718830 | J17: =IF(Salary[[#This Row],[پایه حقوق]]<=5600000,0,(Salary[[#This Row],[پایه حقوق]]-5600000)*0.1) -> 466900 | K17: =G17-I17-J17 -> 9083270
A18: 9988618 | B18: =RANDBETWEEN(30,100) -> 61 | C18: =MATCH(Salary[[#This Row],[ماه]],Calc!$A$16:$A$27,0) -> 1 | D18: فروردین | E18: =RANDBETWEEN(3000,15000)*1000 -> 3910000 | G18: =E18+F18 -> 3910000 | H18: =0.23*E18 -> 899300 | I18: =0.07*E18 -> 273700 | J18: =IF(Salary[[#This Row],[پایه حقوق]]<=5600000,0,(Salary[[#This Row],[پایه حقوق]]-5600000)*0.1) -> 0 | K18: =G18-I18-J18 -> 3636300
A19: 9988657 | B19: =RANDBETWEEN(30,100) -> 55 | C19: =MATCH(Salary[[#This Row],[ماه]],Calc!$A$16:$A$27,0) -> 1 | D19: فروردین | E19: =RANDBETWEEN(3000,15000)*1000 -> 10333000 | F19: =0.7*E19 -> 7233100 | G19: =E19+F19 -> 17566100 | H19: =0.23*E19 -> 2376590 | I19: =0.07*E19 -> 723310 | J19: =IF(Salary[[#This Row],[پایه حقوق]]<=5600000,0,(Salary[[#This Row],[پایه حقوق]]-5600000)*0.1) -> 473300 | K19: =G19-I19-J19 -> 16369490
A20: 9988677 | B20: =RANDBETWEEN(30,100) -> 50 | C20: =MATCH(Salary[[#This Row],[ماه]],Calc!$A$16:$A$27,0) -> 1 | D20: فروردین | E20: =RANDBETWEEN(3000,15000)*1000 -> 11465000 | G20: =E20+F20 -> 11465000 | H20: =0.23*E20 -> 2636950 | I20: =0.07*E20 -> 802550 | J20: =IF(Salary[[#This Row],[پایه حقوق]]<=5600000,0,(Salary[[#This Row],[پایه حقوق]]-5600000)*0.1) -> 586500 | K20: =G20-I20-J20 -> 10075950
A21: 9988725 | B21: =RANDBETWEEN(30,100) -> 86 | C21: =MATCH(Salary[[#This Row],[ماه]],Calc!$A$16:$A$27,0) -> 1 | D21: فروردین | E21: =RANDBETWEEN(3000,15000)*1000 -> 8764000 | F21: =0.7*E21 -> 6134800 | G21: =E21+F21 -> 14898800 | H21: =0.23*E21 -> 2015720 | I21: =0.07*E21 -> 613480 | J21: =IF(Salary[[#This Row],[پایه حقوق]]<=5600000,0,(Salary[[#This Row],[پایه حقوق]]-5600000)*0.1) -> 316400 | K21: =G21-I21-J21 -> 13968920
A22: 9988773 | B22: =RANDBETWEEN(30,100) -> 90 | C22: =MATCH(Salary[[#This Row],[ماه]],Calc!$A$16:$A$27,0) -> 1 | D22: فروردین | E22: =RANDBETWEEN(3000,15000)*1000 -> 7165000 | G22: =E22+F22 -> 7165000 | H22: =0.23*E22 -> 1647950 | I22: =0.07*E22 -> 501550 | J22: =IF(Salary[[#This Row],[پایه حقوق]]<=5600000,0,(Salary[[#This Row],[پایه حقوق]]-5600000)*0.1) -> 156500 | K22: =G22-I22-J22 -> 6506950
A23: 9988821 | B23: =RANDBETWEEN(30,100) -> 89 | C23: =MATCH(Salary[[#This Row],[ماه]],Calc!$A$16:$A$27,0) -> 1 | D23: فروردین | E23: =RANDBETWEEN(3000,15000)*1000 -> 8725000 | G23: =E23+F23 -> 8725000 | H23: =0.23*E23 -> 2006750 | I23: =0.07*E23 -> 610750 | J23: =IF(Salary[[#This Row],[پایه حقوق]]<=5600000,0,(Salary[[#This Row],[پایه حقوق]]-5600000)*0.1) -> 312500 | K23: =G23-I23-J23 -> 7801750
A24: 9988869 | B24: =RANDBETWEEN(30,100) -> 86 | C24: =MATCH(Salary[[#This Row],[ماه]],Calc!$A$16:$A$27,0) -> 1 | D24: فروردین | E24: =RANDBETWEEN(3000,15000)*1000 -> 7507000 | G24: =E24+F24 -> 7507000 | H24: =0.23*E24 -> 1726610 | I24: =0.07*E24 -> 525490 | J24: =IF(Salary[[#This Row],[پایه حقوق]]<=5600000,0,(Salary[[#This Row],[پایه حقوق]]-5600000)*0.1) -> 190700 | K24: =G24-I24-J24 -> 6790810
A25: 9988917 | B25: =RANDBETWEEN(30,100) -> 78 | C25: =MATCH(Salary[[#This Row],[ماه]],Calc!$A$16:$A$27,0) -> 1 | D25: فروردین | E25: =RANDBETWEEN(3000,15000)*1000 -> 10023000 | G25: =E25+F25 -> 10023000 | H25: =0.23*E25 -> 2305290 | I25: =0.07*E25 -> 701610 | J25: =IF(Salary[[#This Row],[پایه حقوق]]<=5600000,0,(Salary[[#This Row],[پایه حقوق]]-5600000)*0.1) -> 442300 | K25: =G25-I25-J25 -> 8879090
A26: 9988965 | B26: =RANDBETWEEN(30,100) -> 97 | C26: =MATCH(Salary[[#This Row],[ماه]],Calc!$A$16:$A$27,0) -> 1 | D26: فروردین | E26: =RANDBETWEEN(3000,15000)*1000 -> 8098000 | G26: =E26+F26 -> 8098000 | H26: =0.23*E26 -> 1862540 | I26: =0.07*E26 -> 566860 | J26: =IF(Salary[[#This Row],[پایه حقوق]]<=5600000,0,(Salary[[#This Row],[پایه حقوق]]-5600000)*0.1) -> 249800 | K26: =G26-I26-J26 -> 7281340
A27: 9989013 | B27: =RANDBETWEEN(30,100) -> 51 | C27: =MATCH(Salary[[#This Row],[ماه]],Calc!$A$16:$A$27,0) -> 1 | D27: فروردین | E27: =RANDBETWEEN(3000,15000)*1000 -> 7440000 | G27: =E27+F27 -> 7440000 | H27: =0.23*E27 -> 1711200 | I27: =0.07*E27 -> 520800 | J27: =IF(Salary[[#This Row],[پایه حقوق]]<=5600000,0,(Salary[[#This Row],[پایه حقوق]]-5600000)*0.1) -> 184000 | K27: =G27-I27-J27 -> 6735200
A28: 9989061 | B28: =RANDBETWEEN(30,100) -> 52 | C28: =MATCH(Salary[[#This Row],[ماه]],Calc!$A$16:$A$27,0) -> 1 | D28: فروردین | E28: =RANDBETWEEN(3000,15000)*1000 -> 11571000 | G28: =E28+F28 -> 11571000 | H28: =0.23*E28 -> 2661330 | I28: =0.07*E28 -> 809970 | J28: =IF(Salary[[#This Row],[پایه حقوق]]<=5600000,0,(Salary[[#This Row],[پایه حقوق]]-5600000)*0.1) -> 597100 | K28: =G28-I28-J28 -> 10163930
A29: 9989109 | B29: =RANDBETWEEN(30,100) -> 38 | C29: =MATCH(Salary[[#This Row],[ماه]],Calc!$A$16:$A$27,0) -> 1 | D29: فروردین | E29: =RANDBETWEEN(3000,15000)*1000 -> 5432000 | G29: =E29+F29 -> 5432000 | H29: =0.23*E29 -> 1249360 | I29: =0.07*E29 -> 380240 | J29: =IF(Salary[[#This Row],[پایه حقوق]]<=5600000,0,(Salary[[#This Row],[پایه حقوق]]-5600000)*0.1) -> 0 | K29: =G29-I29-J29 -> 5051760
A30: 9989157 | B30: =RANDBETWEEN(30,100) -> 55 | C30: =MATCH(Salary[[#This Row],[ماه]],Calc!$A$16:$A$27,0) -> 1 | D30: فروردین | E30: =RANDBETWEEN(3000,15000)*1000 -> 10325000 | G30: =E30+F30 -> 10325000 | H30: =0.23*E30 -> 2374750 | I30: =0.07*E30 -> 722750 | J30: =IF(Salary[[#This Row],[پایه حقوق]]<=5600000,0,(Salary[[#This Row],[پایه حقوق]]-5600000)*0.1) -> 472500 | K30: =G30-I30-J30 -> 9129750
A31: 9989205 | B31: =RANDBETWEEN(30,100) -> 61 | C31: =MATCH(Salary[[#This Row],[ماه]],Calc!$A$16:$A$27,0) -> 1 | D31: فروردین | E31: =RANDBETWEEN(3000,15000)*1000 -> 14785000 | G31: =E31+F31 -> 14785000 | H31: =0.23*E31 -> 3400550 | I31: =0.07*E31 -> 1034950 | J31: =IF(Salary[[#This Row],[پایه حقوق]]<=5600000,0,(Salary[[#This Row],[پایه حقوق]]-5600000)*0.1) -> 918500 | K31: =G31-I31-J31 -> 12831550
A32: 9989253 | B32: =RANDBETWEEN(30,100) -> 97 | C32: =MATCH(Salary[[#This Row],[ماه]],Calc!$A$16:$A$27,0) -> 1 | D32: فروردین | E32: =RANDBETWEEN(3000,15000)*1000 -> 10871000 | G32: =E32+F32 -> 10871000 | H32: =0.23*E32 -> 2500330 | I32: =0.07*E32 -> 760970 | J32: =IF(Salary[[#This Row],[پایه حقوق]]<=5600000,0,(Salary[[#This Row],[پایه حقوق]]-5600000)*0.1) -> 527100 | K32: =G32-I32-J32 -> 9582930
A33: 9989301 | B33: =RANDBETWEEN(30,100) -> 89 | C33: =MATCH(Salary[[#This Row],[ماه]],Calc!$A$16:$A$27,0) -> 1 | D33: فروردین | E33: =RANDBETWEEN(3000,15000)*1000 -> 4066000 | G33: =E33+F33 -> 4066000 | H33: =0.23*E33 -> 935180 | I33: =0.07*E33 -> 284620 | J33: =IF(Salary[[#This Row],[پایه حقوق]]<=5600000,0,(Salary[[#This Row],[پایه حقوق]]-5600000)*0.1) -> 0 | K33: =G33-I33-J33 -> 3781380
... A122: 9987656 | B122: =RANDBETWEEN(30,100) -> 44 | C122: =MATCH(Salary[[#This Row],[ماه]],Calc!$A$16:$A$27,0) -> 3 | D122: خرداد | E122: =RANDBETWEEN(3000,15000)*1000 -> 8734000 | G122: =E122+F122 -> 8734000 | H122: =0.23*E122 -> 2008820 | I122: =0.07*E122 -> 611380 | J122: =IF(Salary[[#This Row],[پایه حقوق]]<=5600000,0,(Salary[[#This Row],[پایه حقوق]]-5600000)*0.1) -> 313400 | K122: =G122-I122-J122 -> 7809220
A123: 9987728 | B123: =RANDBETWEEN(30,100) -> 79 | C123: =MATCH(Salary[[#This Row],[ماه]],Calc!$A$16:$A$27,0) -> 3 | D123: خرداد | E123: =RANDBETWEEN(3000,15000)*1000 -> 11185000 | F123: =0.7*E123 -> 7829500 | G123: =E123+F123 -> 19014500 | H123: =0.23*E123 -> 2572550 | I123: =0.07*E123 -> 782950 | J123: =IF(Salary[[#This Row],[پایه حقوق]]<=5600000,0,(Salary[[#This Row],[پایه حقوق]]-5600000)*0.1) -> 558500 | K123: =G123-I123-J123 -> 17673050
A124: 9987826 | B124: =RANDBETWEEN(30,100) -> 64 | C124: =MATCH(Salary[[#This Row],[ماه]],Calc!$A$16:$A$27,0) -> 3 | D124: خرداد | E124: =RANDBETWEEN(3000,15000)*1000 -> 8814000 | G124: =E124+F124 -> 8814000 | H124: =0.23*E124 -> 2027220 | I124: =0.07*E124 -> 616980 | J124: =IF(Salary[[#This Row],[پایه حقوق]]<=5600000,0,(Salary[[#This Row],[پایه حقوق]]-5600000)*0.1) -> 321400 | K124: =G124-I124-J124 -> 7875620
A125: 9987915 | B125: =RANDBETWEEN(30,100) -> 79 | C125: =MATCH(Salary[[#This Row],[ماه]],Calc!$A$16:$A$27,0) -> 3 | D125: خرداد | E125: =RANDBETWEEN(3000,15000)*1000 -> 6212000 | G125: =E125+F125 -> 6212000 | H125: =0.23*E125 -> 1428760 | I125: =0.07*E125 -> 434840 | J125: =IF(Salary[[#This Row],[پایه حقوق]]<=5600000,0,(Salary[[#This Row],[پایه حقوق]]-5600000)*0.1) -> 61200 | K125: =G125-I125-J125 -> 5715960
A126: 9987938 | B126: =RANDBETWEEN(30,100) -> 51 | C126: =MATCH(Salary[[#This Row],[ماه]],Calc!$A$16:$A$27,0) -> 3 | D126: خرداد | E126: =RANDBETWEEN(3000,15000)*1000 -> 10891000 | G126: =E126+F126 -> 10891000 | H126: =0.23*E126 -> 2504930 | I126: =0.07*E126 -> 762370 | J126: =IF(Salary[[#This Row],[پایه حقوق]]<=5600000,0,(Salary[[#This Row],[پایه حقوق]]-5600000)*0.1) -> 529100 | K126: =G126-I126-J126 -> 9599530
A127: 9988023 | B127: =RANDBETWEEN(30,100) -> 92 | C127: =MATCH(Salary[[#This Row],[ماه]],Calc!$A$16:$A$27,0) -> 3 | D127: خرداد | E127: =RANDBETWEEN(3000,15000)*1000 -> 8120000 | G127: =E127+F127 -> 8120000 | H127: =0.23*E127 -> 1867600 | I127: =0.07*E127 -> 568400 | J127: =IF(Salary[[#This Row],[پایه حقوق]]<=5600000,0,(Salary[[#This Row],[پایه حقوق]]-5600000)*0.1) -> 252000 | K127: =G127-I127-J127 -> 7299600
A128: 9988106 | B128: =RANDBETWEEN(30,100) -> 73 | C128: =MATCH(Salary[[#This Row],[ماه]],Calc!$A$16:$A$27,0) -> 3 | D128: خرداد | E128: =RANDBETWEEN(3000,15000)*1000 -> 7748000 | G128: =E128+F128 -> 7748000 | H128: =0.23*E128 -> 1782040 | I128: =0.07*E128 -> 542360 | J128: =IF(Salary[[#This Row],[پایه حقوق]]<=5600000,0,(Salary[[#This Row],[پایه حقوق]]-5600000)*0.1) -> 214800 | K128: =G128-I128-J128 -> 6990840
...

Sheet Sheet3
A3: Row Labels
A4: حقوقی و قراردادی
A5: فناوری اطلاعات
A6: کنترل هزینه
A7: منابع انسانی
A8: مهندسی
A9: Grand Total

Sheet HR
A5: داشبورد منابع انسانی
A6: داشبورد منابع مالی

Sheet Finance
A5: داشبورد منابع انسانی
A6: داشبورد منابع مالی
